Traceback (most recent call last):
  File "/home/kishor0000/anaconda3/envs/autograde/lib/python3.10/site-packages/jupyter_cache/executors/utils.py", line 51, in single_nb_execution
    executenb(
  File "/home/kishor0000/anaconda3/envs/autograde/lib/python3.10/site-packages/nbclient/client.py", line 1204, in execute
    return NotebookClient(nb=nb, resources=resources, km=km, **kwargs).execute()
  File "/home/kishor0000/anaconda3/envs/autograde/lib/python3.10/site-packages/nbclient/util.py", line 84, in wrapped
    return just_run(coro(*args, **kwargs))
  File "/home/kishor0000/anaconda3/envs/autograde/lib/python3.10/site-packages/nbclient/util.py", line 62, in just_run
    return loop.run_until_complete(coro)
  File "/home/kishor0000/anaconda3/envs/autograde/lib/python3.10/asyncio/base_events.py", line 646, in run_until_complete
    return future.result()
  File "/home/kishor0000/anaconda3/envs/autograde/lib/python3.10/site-packages/nbclient/client.py", line 663, in async_execute
    await self.async_execute_cell(
  File "/home/kishor0000/anaconda3/envs/autograde/lib/python3.10/site-packages/nbclient/client.py", line 965, in async_execute_cell
    await self._check_raise_for_error(cell, cell_index, exec_reply)
  File "/home/kishor0000/anaconda3/envs/autograde/lib/python3.10/site-packages/nbclient/client.py", line 862, in _check_raise_for_error
    raise CellExecutionError.from_cell_and_msg(cell, exec_reply_content)
nbclient.exceptions.CellExecutionError: An error occurred while executing the following cell:
------------------
 def wf(y, SXX, sigma, ker=np.ones((1, 1))):
    F_y = fft2(y)
    F_ker = fft2(ker, shape=y.shape)
    F_wiener = np.conj(F_ker)*SXX / ( SXX*np.abs(F_ker)**2 + np.prod(y.shape) * sigma**2)
    F_x_hat = F_y * F_wiener
    x_hat = np.real(ifft2(F_x_hat))
    return x_hat, np.real(ifft2(F_wiener))


x_wiener, filt2 = wf(x_blur_n, SXX, sig, ker=h_gauss)

fig, axs = plt.subplots(1, 2, figsize=(15, 10))
axs[0].imshow(x_wiener, cmap='gray')
axs[1].imshow(x_wiener[100:170, 200:300], cmap='gray');
------------------

[0;31m---------------------------------------------------------------------------[0m
[0;31mNameError[0m                                 Traceback (most recent call last)
Cell [0;32mIn[8], line 10[0m
[1;32m      6[0m    x_hat [38;5;241m=[39m np[38;5;241m.[39mreal(ifft2(F_x_hat))
[1;32m      7[0m    [38;5;28;01mreturn[39;00m x_hat, np[38;5;241m.[39mreal(ifft2(F_wiener))
[0;32m---> 10[0m x_wiener, filt2 [38;5;241m=[39m wf(x_blur_n, [43mSXX[49m, sig, ker[38;5;241m=[39mh_gauss)
[1;32m     12[0m fig, axs [38;5;241m=[39m plt[38;5;241m.[39msubplots([38;5;241m1[39m, [38;5;241m2[39m, figsize[38;5;241m=[39m([38;5;241m15[39m, [38;5;241m10[39m))
[1;32m     13[0m axs[[38;5;241m0[39m][38;5;241m.[39mimshow(x_wiener, cmap[38;5;241m=[39m[38;5;124m'[39m[38;5;124mgray[39m[38;5;124m'[39m)

[0;31mNameError[0m: name 'SXX' is not defined
NameError: name 'SXX' is not defined

