Traceback (most recent call last):
  File "C:\Users\nguyen0004\AppData\Roaming\Python\Python37\site-packages\nbclient\client.py", line 730, in _async_poll_for_reply
    msg = await ensure_async(self.kc.shell_channel.get_msg(timeout=new_timeout))
  File "C:\Users\nguyen0004\AppData\Roaming\Python\Python37\site-packages\nbclient\util.py", line 96, in ensure_async
    result = await obj
  File "C:\Users\nguyen0004\Anaconda3\envs\rir\lib\site-packages\jupyter_client\channels.py", line 231, in get_msg
    raise Empty
_queue.Empty

During handling of the above exception, another exception occurred:

Traceback (most recent call last):
  File "C:\Users\nguyen0004\AppData\Roaming\Python\Python37\site-packages\jupyter_cache\executors\utils.py", line 56, in single_nb_execution
    record_timing=False,
  File "C:\Users\nguyen0004\AppData\Roaming\Python\Python37\site-packages\nbclient\client.py", line 1204, in execute
    return NotebookClient(nb=nb, resources=resources, km=km, **kwargs).execute()
  File "C:\Users\nguyen0004\AppData\Roaming\Python\Python37\site-packages\nbclient\util.py", line 84, in wrapped
    return just_run(coro(*args, **kwargs))
  File "C:\Users\nguyen0004\AppData\Roaming\Python\Python37\site-packages\nbclient\util.py", line 62, in just_run
    return loop.run_until_complete(coro)
  File "C:\Users\nguyen0004\Anaconda3\envs\rir\lib\asyncio\base_events.py", line 587, in run_until_complete
    return future.result()
  File "C:\Users\nguyen0004\AppData\Roaming\Python\Python37\site-packages\nbclient\client.py", line 664, in async_execute
    cell, index, execution_count=self.code_cells_executed + 1
  File "C:\Users\nguyen0004\AppData\Roaming\Python\Python37\site-packages\nbclient\client.py", line 949, in async_execute_cell
    exec_reply = await self.task_poll_for_reply
  File "C:\Users\nguyen0004\AppData\Roaming\Python\Python37\site-packages\nbclient\client.py", line 754, in _async_poll_for_reply
    await self._async_handle_timeout(timeout, cell)
  File "C:\Users\nguyen0004\AppData\Roaming\Python\Python37\site-packages\nbclient\client.py", line 802, in _async_handle_timeout
    "Cell execution timed out", timeout, cell
nbclient.exceptions.CellTimeoutError: A cell timed out while it was being executed, after 120 seconds.
The message was: Cell execution timed out.
Here is a preview of the cell contents:
-------------------
['k = 31', 'error_count = 0', 'for i_example in range(n):', '', '    # compute distance from the current example']
...
['    # check for errors', '    if y_est * y[i_example] < 0:', '        error_count += 1', '', 'print("The number of misclassified points is: ", error_count)']
-------------------

