Traceback (most recent call last):
  File "C:\Users\nguyen0004\AppData\Roaming\Python\Python37\site-packages\jupyter_cache\executors\utils.py", line 56, in single_nb_execution
    record_timing=False,
  File "C:\Users\nguyen0004\AppData\Roaming\Python\Python37\site-packages\nbclient\client.py", line 1204, in execute
    return NotebookClient(nb=nb, resources=resources, km=km, **kwargs).execute()
  File "C:\Users\nguyen0004\AppData\Roaming\Python\Python37\site-packages\nbclient\util.py", line 84, in wrapped
    return just_run(coro(*args, **kwargs))
  File "C:\Users\nguyen0004\AppData\Roaming\Python\Python37\site-packages\nbclient\util.py", line 62, in just_run
    return loop.run_until_complete(coro)
  File "C:\Users\nguyen0004\Anaconda3\envs\rir\lib\asyncio\base_events.py", line 587, in run_until_complete
    return future.result()
  File "C:\Users\nguyen0004\AppData\Roaming\Python\Python37\site-packages\nbclient\client.py", line 664, in async_execute
    cell, index, execution_count=self.code_cells_executed + 1
  File "C:\Users\nguyen0004\AppData\Roaming\Python\Python37\site-packages\nbclient\client.py", line 965, in async_execute_cell
    await self._check_raise_for_error(cell, cell_index, exec_reply)
  File "C:\Users\nguyen0004\AppData\Roaming\Python\Python37\site-packages\nbclient\client.py", line 862, in _check_raise_for_error
    raise CellExecutionError.from_cell_and_msg(cell, exec_reply_content)
nbclient.exceptions.CellExecutionError: An error occurred while executing the following cell:
------------------
from mlxtend.data import loadlocal_mnist

X_train, y_train = loadlocal_mnist(
        images_path='/Users/dokman0000/Downloads/train-images-idx3-ubyte', 
        labels_path='/Users/dokman0000/Downloads/train-labels-idx1-ubyte'
        )

fig, axs = plt.subplots(ncols=4, nrows=1, figsize=(14, 3))
for ax in axs:
    ax.imshow(X_train[np.random.randint(1000)].reshape(28, 28), cmap='gray')
------------------

[1;31m---------------------------------------------------------------------------[0m
[1;31mModuleNotFoundError[0m                       Traceback (most recent call last)
[1;32m~\AppData\Local\Temp\ipykernel_15356\106244075.py[0m in [0;36m<module>[1;34m[0m
[1;32m----> 1[1;33m [1;32mfrom[0m [0mmlxtend[0m[1;33m.[0m[0mdata[0m [1;32mimport[0m [0mloadlocal_mnist[0m[1;33m[0m[1;33m[0m[0m
[0m[0;32m      2[0m [1;33m[0m[0m
[0;32m      3[0m X_train, y_train = loadlocal_mnist(
[0;32m      4[0m         [0mimages_path[0m[1;33m=[0m[1;34m'/Users/dokman0000/Downloads/train-images-idx3-ubyte'[0m[1;33m,[0m[1;33m[0m[1;33m[0m[0m
[0;32m      5[0m         [0mlabels_path[0m[1;33m=[0m[1;34m'/Users/dokman0000/Downloads/train-labels-idx1-ubyte'[0m[1;33m[0m[1;33m[0m[0m

[1;31mModuleNotFoundError[0m: No module named 'mlxtend'
ModuleNotFoundError: No module named 'mlxtend'

