Traceback (most recent call last):
  File "C:\Users\nguyen0004\AppData\Roaming\Python\Python37\site-packages\jupyter_cache\executors\utils.py", line 56, in single_nb_execution
    record_timing=False,
  File "C:\Users\nguyen0004\AppData\Roaming\Python\Python37\site-packages\nbclient\client.py", line 1204, in execute
    return NotebookClient(nb=nb, resources=resources, km=km, **kwargs).execute()
  File "C:\Users\nguyen0004\AppData\Roaming\Python\Python37\site-packages\nbclient\util.py", line 84, in wrapped
    return just_run(coro(*args, **kwargs))
  File "C:\Users\nguyen0004\AppData\Roaming\Python\Python37\site-packages\nbclient\util.py", line 62, in just_run
    return loop.run_until_complete(coro)
  File "C:\Users\nguyen0004\Anaconda3\envs\rir\lib\asyncio\base_events.py", line 587, in run_until_complete
    return future.result()
  File "C:\Users\nguyen0004\AppData\Roaming\Python\Python37\site-packages\nbclient\client.py", line 664, in async_execute
    cell, index, execution_count=self.code_cells_executed + 1
  File "C:\Users\nguyen0004\AppData\Roaming\Python\Python37\site-packages\nbclient\client.py", line 965, in async_execute_cell
    await self._check_raise_for_error(cell, cell_index, exec_reply)
  File "C:\Users\nguyen0004\AppData\Roaming\Python\Python37\site-packages\nbclient\client.py", line 862, in _check_raise_for_error
    raise CellExecutionError.from_cell_and_msg(cell, exec_reply_content)
nbclient.exceptions.CellExecutionError: An error occurred while executing the following cell:
------------------
fig, ax = plt.subplots(1, 1, figsize=(8, 5))

ax.bar(np.arange(30) - 0.2, males, width=0.4)
ax.bar(np.arange(30) + 0.2, females, width=0.4)

ax.legend(['Male', 'Female'], frameon=False)
ax.set_xlabel('Number of rings')
ax.set_ylabel('Number of snails');
------------------

[1;31m---------------------------------------------------------------------------[0m
[1;31mNameError[0m                                 Traceback (most recent call last)
[1;32m~\AppData\Local\Temp\ipykernel_18196\3506181457.py[0m in [0;36m<module>[1;34m[0m
[0;32m      1[0m [0mfig[0m[1;33m,[0m [0max[0m [1;33m=[0m [0mplt[0m[1;33m.[0m[0msubplots[0m[1;33m([0m[1;36m1[0m[1;33m,[0m [1;36m1[0m[1;33m,[0m [0mfigsize[0m[1;33m=[0m[1;33m([0m[1;36m8[0m[1;33m,[0m [1;36m5[0m[1;33m)[0m[1;33m)[0m[1;33m[0m[1;33m[0m[0m
[0;32m      2[0m [1;33m[0m[0m
[1;32m----> 3[1;33m [0max[0m[1;33m.[0m[0mbar[0m[1;33m([0m[0mnp[0m[1;33m.[0m[0marange[0m[1;33m([0m[1;36m30[0m[1;33m)[0m [1;33m-[0m [1;36m0.2[0m[1;33m,[0m [0mmales[0m[1;33m,[0m [0mwidth[0m[1;33m=[0m[1;36m0.4[0m[1;33m)[0m[1;33m[0m[1;33m[0m[0m
[0m[0;32m      4[0m [0max[0m[1;33m.[0m[0mbar[0m[1;33m([0m[0mnp[0m[1;33m.[0m[0marange[0m[1;33m([0m[1;36m30[0m[1;33m)[0m [1;33m+[0m [1;36m0.2[0m[1;33m,[0m [0mfemales[0m[1;33m,[0m [0mwidth[0m[1;33m=[0m[1;36m0.4[0m[1;33m)[0m[1;33m[0m[1;33m[0m[0m
[0;32m      5[0m [1;33m[0m[0m

[1;31mNameError[0m: name 'males' is not defined
NameError: name 'males' is not defined

